<?xml version="1.0"?>
<robot
  name="rover_mod">
  <link name="base_link">
    <inertial>
      <origin
        xyz="3.7045E-17 -0.0006414 -2.3116E-17"
        rpy="0 0 0" />
      <mass
        value="0.022865" />
      <inertia
        ixx="6.483E-05"
        ixy="3.3859E-20"
        ixz="-3.1265E-20"
        iyy="0.00012929"
        iyz="1.2088E-20"
        izz="6.483E-05" />
    </inertial>
    <visual>
      <origin
        xyz="0 0 0"
        rpy="0 0 0" />
      <geometry>
        <mesh
          filename="package://rover_mod/meshes/base_link.STL" />
      </geometry>
      <material
        name="">
        <color
          rgba="0.95686 0.95686 0.95686 1" />
      </material>
    </visual>
    <collision>
      <origin
        xyz="0 0 0"
        rpy="0 0 0" />
      <geometry>
        <mesh
          filename="package://rover_mod/meshes/base_link.STL" />
      </geometry>
    </collision>
  </link>

  <link name="Link 1">
    <inertial>
      <origin
        xyz="-0.034453 0.035961 0.0024172"
        rpy="0 0 0" />
      <mass
        value="2.4855" />
      <inertia
        ixx="0.0012503"
        ixy="-0.00019461"
        ixz="-0.00010061"
        iyy="0.0034899"
        iyz="9.8668E-06"
        izz="0.003064" />
    </inertial>
    <visual>
      <origin
        xyz="0 0 0"
        rpy="0 0 0" />
      <geometry>
        <mesh
          filename="package://rover_mod/meshes/Link 1.STL" />
      </geometry>
      <material
        name="">
        <color
          rgba="0.79216 0.81961 0.93333 1" />
      </material>
    </visual>
    <collision>
      <origin
        xyz="0 0 0"
        rpy="0 0 0" />
      <geometry>
        <mesh
          filename="package://rover_mod/meshes/Link 1.STL" />
      </geometry>
    </collision>
  </link>
  <joint name="Joint 1"
    type="continuous">
    <origin
      xyz="0 0 0"
      rpy="1.5707963267949 1.32828033133795E-16 2.4329912162412" />
    <parent
      link="base_link" />
    <child
      link="Link 1" />
    <axis
      xyz="0 -1 0" />
  </joint>

  <link name="Link 2">
    <inertial>
      <origin
        xyz="2.11434774587266E-05 9.34128079055352E-09 0.063978675315493"
        rpy="0 0 0" />
      <mass
        value="0.124942866372761" />
      <inertia
        ixx="0.000273082402914828"
        ixy="-2.30869477859221E-11"
        ixz="8.58944823118754E-09"
        iyy="0.00070362386385363"
        iyz="4.04286705194435E-11"
        izz="0.00055656824637952" />
    </inertial>
    <visual>
      <origin
        xyz="0 0 0"
        rpy="0 0 0" />
      <geometry>
        <mesh
          filename="package://rover_mod/meshes/Link 2.STL" />
      </geometry>
      <material
        name="">
        <color
          rgba="0.792156862745098 0.819607843137255 0.933333333333333 1" />
      </material>
    </visual>
    <collision>
      <origin
        xyz="0 0 0"
        rpy="0 0 0" />
      <geometry>
        <mesh
          filename="package://rover_mod/meshes/Link 2.STL" />
      </geometry>
    </collision>
  </link>
  <joint name="Joint 2"
    type="continuous">
    <origin
      xyz="-0.127 0.044576 0"
      rpy="1.7457 -1.5708 0" />
    <parent
      link="Link 1" />
    <child
      link="Link 2" />
    <axis
      xyz="-1 0 0" />
  </joint>

  <link name="Link 3">
    <inertial>
      <origin
        xyz="-0.094675 0.010083 0.0054822"
        rpy="0 0 0" />
      <mass
        value="2.42066" />
      <inertia
        ixx="0.0010878"
        ixy="-0.00027771"
        ixz="1.0893E-06"
        iyy="0.0036811"
        iyz="-2.8779E-07"
        izz="0.0030266" />
    </inertial>
    <visual>
      <origin
        xyz="0 0 0"
        rpy="0 0 0" />
      <geometry>
        <mesh
          filename="package://rover_mod/meshes/Link 3.STL" />
      </geometry>
      <material
        name="">
        <color
          rgba="0.79216 0.81961 0.93333 1" />
      </material>
    </visual>
    <collision>
      <origin
        xyz="0 0 0"
        rpy="0 0 0" />
      <geometry>
        <mesh
          filename="package://rover_mod/meshes/Link 3.STL" />
      </geometry>
    </collision>
  </link>
  <joint name="Joint 3"
    type="continuous">
    <origin
      xyz="0 0 0.127"
      rpy="-1.5707963267949 -0.195110840981509 -1.5707963267949" />
    <parent
      link="Link 2" />
    <child
      link="Link 3" />
    <axis
      xyz="0 0 -1" />
  </joint>

  <link name="Link 4">
    <inertial>
      <origin
        xyz="-0.11033 -0.0030809 8.0401E-05"
        rpy="0 0 0" />
      <mass
        value="0.8014" />
      <inertia
        ixx="0.00075276"
        ixy="2.2927E-05"
        ixz="-4.1385E-07"
        iyy="0.0014626"
        iyz="-1.9711E-08"
        izz="0.00089769" />
    </inertial>
    <visual>
      <origin
        xyz="0 0 0"
        rpy="0 0 0" />
      <geometry>
        <mesh
          filename="package://rover_mod/meshes/Link 4.STL" />
      </geometry>
      <material
        name="">
        <color
          rgba="0.79216 0.81961 0.93333 1" />
      </material>
    </visual>
    <collision>
      <origin
        xyz="0 0 0"
        rpy="0 0 0" />
      <geometry>
        <mesh
          filename="package://rover_mod/meshes/Link 4.STL" />
      </geometry>
    </collision>
  </link>
  <joint name="Joint 4"
    type="continuous">
    <origin
      xyz="-0.18943 0.020122 0"
      rpy="-4.0523E-15 -3.0947E-15 1.8309" />
    <parent
      link="Link 3" />
    <child
      link="Link 4" />
    <axis
      xyz="0 0 -1" />
  </joint>

  <link name="Gripper">
    <inertial>
      <origin
        xyz="0.12317 -5.3594E-05 0.0011873"
        rpy="0 0 0" />
      <mass
        value="0.84161" />
      <inertia
        ixx="0.0011814"
        ixy="-6.1852E-07"
        ixz="3.7374E-06"
        iyy="0.0019494"
        iyz="4.9411E-06"
        izz="0.00099774" />
    </inertial>
    <visual>
      <origin
        xyz="0 0 0"
        rpy="0 0 0" />
      <geometry>
        <mesh
          filename="package://rover_mod/meshes/Gripper.STL" />
      </geometry>
      <material
        name="">
        <color
          rgba="0.79216 0.81961 0.93333 1" />
      </material>
    </visual>
    <collision>
      <origin
        xyz="0 0 0"
        rpy="0 0 0" />
      <geometry>
        <mesh
          filename="package://rover_mod/meshes/Gripper.STL" />
      </geometry>
    </collision>
  </link>
  <joint name="Gripper Joint"
    type="continuous">
    <origin
      xyz="-0.137852008201683 0 0.000164409881997847"
      rpy="-2.57645174662975 -2.08166817117217E-16 -3.14159265358979" />
    <parent
      link="Link 4" />
    <child
      link="Gripper" />
    <axis
      xyz="-1 0 0" />
  </joint>
</robot>
